<mujoco model="arx7">
  <compiler angle="radian" meshdir="./meshes/"/>
  <option timestep="0.002" integrator="RK4" gravity="0 0 -9.806" solver="Newton" noslip_iterations="0"/>
  <size njmax="10000" nconmax="10000"/>
  <default>
    <geom contype="1" conaffinity="1" rgba="0.5 0.6 0.7 1" margin="0.001" group="0"/>
    <motor gear="20" ctrllimited="true" ctrlrange="-40 40" />
    <position gear="10" ctrllimited="true" kp="5"/>
    <joint limited="true" frictionloss="0.5" damping="45" armature="0.1"/>
  </default>

  <asset>
    <mesh name="base_link" file="chassis/base_link.STL"/>
    <mesh name="left_thigh" file="chassis/left_thigh.STL"/>
    <mesh name="left_shin" file="chassis/left_shin.STL"/>
    <mesh name="left_wheel" file="chassis/left_wheel.STL"/>
    <mesh name="right_thigh" file="chassis/right_thigh.STL"/>
    <mesh name="right_shin" file="chassis/right_shin.STL"/>
    <mesh name="right_wheel" file="chassis/right_wheel.STL"/>

    <mesh name="stair1" file="stair/stair1.STL"/>
    <mesh name="stair2" file="stair/stair2.STL"/>
    <mesh name="stair3" file="stair/stair3.STL"/>
    <mesh name="stair4" file="stair/stair4.STL"/>
    <mesh name="stair5" file="stair/stair5.STL"/>
  </asset>

  <asset>
    <texture name="grid" type="2d" builtin="checker" rgb1=".9 .8 .7" rgb2=".4 .4 .4" width="300" height="300" mark="edge" markrgb=".2 .3 .4"/>
    <material name="grid" texture="grid" texrepeat="2 2" texuniform="true" reflectance=".2"/>
  </asset>

  <visual>
    <global offwidth="1920" offheight="1080"/>
    <rgba com="0.502 1.0 0 0.5" contactforce="0.98 0.4 0.4 0.7" contactpoint="1.0 1.0 0.6 0.4"/>
    <scale com="0.2" forcewidth="0.035" contactwidth="0.10" contactheight="0.04"/>
  </visual>

  <worldbody>
    <light directional="true" diffuse=".8 .8 .8" pos="0 0 10" dir="0 0 -10"/>
    <light pos="0.5 -.4 1." dir="1 2 -1.5" diffuse=".6 .6 .6"/>
    <camera name="top" pos="0. 0. 2." xyaxes="1.000 0.0 0.000 0.0 1.000 0.017"/>
    <camera name="left" pos="0. 1 0.3" xyaxes="-1. 0. 0. 0. 0. 1."/>
    <camera name="right" pos="0. -1 0.3" xyaxes="1. 0. 0. 0. 0. 1."/>
    <camera name="track" mode="trackcom" fovy="45" pos="0.5 -1. 0.35" xyaxes="0.866 0.5 0 0 0 1"/>
    <geom name="ground" type="plane" pos="0 0 0" size="20 20 0.1" material="grid" solimp=".9 .95 .001" solref='-10000 -1000'/>

    <geom name="box1" pos="-0.6 1.5 0.14" size="0.6 0.5 0.03" type="box" rgba="1 0.6 0.8 1" euler="0 0.06 0" conaffinity="1"/>
    <geom name="box1r" pos="-0.6 0.5 0.2" size="0.6 0.5 0.03" type="box" rgba="1 1 1 1" euler="0 -0.03 0" conaffinity="1"/>
    <geom name="box2" pos="-2 1 0.18" size="0.8 1 0.03" type="box" rgba="1 1 1 1" euler="0 0 0" conaffinity="1"/>
    <geom name="box3" pos="-3.3 1.5 0.18" size="0.5 0.5 0.03" type="box" rgba="1 0.6 0.8 1" euler="0 0 0" conaffinity="1"/>
    <geom name="box3r" pos="-3.4 0.5 0.15" size="0.6 0.5 0.03" type="box" rgba="1 0.6 0.8 1" euler="0 -0.05 0" conaffinity="1"/>
    <geom name="box4" pos="-4.4 1.5 0.18" size="0.6 0.5 0.03" type="box" rgba="1 1 1 1" euler="0 0 0" conaffinity="1"/>
    <geom name="box4r" pos="-4.8 0.5 0.16" size="0.8 0.5 0.03" type="box" rgba="1 0.6 0.8 1" euler="0 0.05 0" conaffinity="1"/>
    <geom name="box5" pos="-5.7 1.5 0.14" size="0.7 0.5 0.03" type="box" rgba="1 0.6 0.8 1" euler="0 -0.05 -0" conaffinity="1"/>
    <geom name="box5r" pos="-6.2 0.5 0.2" size="0.6 0.5 0.03" type="box" rgba="1 1 1 1" euler="0 0 0" conaffinity="1"/>
    <geom name="box6" pos="-7.1 1.5 0.14" size="0.7 0.5 0.03" type="box" rgba="1 0.6 0.8 1" euler="0 0.05 0" conaffinity="1"/>
    <geom name="box6r" pos="-7.3 0.5 0.19" size="0.5 0.5 0.03" type="box" rgba="1 0.6 0.8 1" euler="0 -0.02 0" conaffinity="1"/>
    <geom name="box7" pos="-8.8 1 0.18" size="1 1 0.03" type="box" rgba="1 1 1 1" euler="0 0 0" conaffinity="1"/>

    <geom name="box8" pos="9.2 1 0.32" size="1 1 0.03" type="box" rgba="1 1 1 1" euler="0 0 0" conaffinity="1"/>
    <geom name="stair1" type="mesh" mesh="stair1" pos="7.8 0 0.11" rgba="1 0.6 0.8 1"/>
    <geom name="stair2" type="mesh" mesh="stair3" pos="8 0 0.05" rgba="1 0.6 0.8 1"/>
    <geom name="box9r" pos="7.3 0.5 0.19" size="0.5 0.5 0.03" type="box" rgba="1 0.6 0.8 1" euler="0 0.02 0" conaffinity="1"/>
    <geom name="box9" pos="7.1 1.5 0.14" size="0.7 0.5 0.03" type="box" rgba="1 0.6 0.8 1" euler="0 -0.05 0" conaffinity="1"/>
    <geom name="box10r" pos="6.2 0.5 0.2" size="0.6 0.5 0.03" type="box" rgba="1 1 1 1" euler="0 0 0" conaffinity="1"/>
    <geom name="box10" pos="5.7 1.5 0.14" size="0.7 0.5 0.03" type="box" rgba="1 0.6 0.8 1" euler="0 0.05 -0" conaffinity="1"/>
    <geom name="box11r" pos="4.8 0.5 0.16" size="0.8 0.5 0.03" type="box" rgba="1 0.6 0.8 1" euler="0 -0.05 0" conaffinity="1"/>
    <geom name="box11" pos="4.4 1.5 0.18" size="0.6 0.5 0.03" type="box" rgba="1 1 1 1" euler="0 0 0" conaffinity="1"/>
    <geom name="box12r" pos="3.4 0.5 0.15" size="0.6 0.5 0.03" type="box" rgba="1 0.6 0.8 1" euler="0 0.05 0" conaffinity="1"/>
    <geom name="box12" pos="3.3 1.5 0.18" size="0.5 0.5 0.03" type="box" rgba="1 0.6 0.8 1" euler="0 0 0" conaffinity="1"/>
    <geom name="box13" pos="2.2 1 0.18" size="0.6 1 0.03" type="box" rgba="1 1 1 1" euler="0 0.01 0" conaffinity="1"/>
    <geom name="box14" pos="0.8 1.5 0.145" size="0.8 0.5 0.03" type="box" rgba="1 1 1 1" euler="0 -0.05 0" conaffinity="1"/>
    <geom name="box14r" pos="0.8 0.5 0.2" size="0.8 0.5 0.03" type="box" rgba="1 0.6 0.8 1" euler="0 0.02 0" conaffinity="1"/>

    <geom name="obs1" pos="4.3 1.3 0.218" size="0.15 0.2 0.01" type="box" rgba="1 0.6 0.8 1" euler="0 0 -0.4" conaffinity="1"/>
    <geom name="obs2" pos="3.5 0.6 0.175" size="0.2 0.15 0.01" type="box" rgba="1 1 1 1" euler="0 0.05 0.3" conaffinity="1"/>
    <geom name="obs3" pos="3.2 1.5 0.218" size="0.15 0.2 0.01" type="box" rgba="1 1 1 1" euler="0 0 -0.7" conaffinity="1"/>
    <geom name="obs4" pos="2.3 0.7 0.218" size="0.2 0.15 0.01" type="box" rgba="1 0.6 0.8 1" euler="0 -0.01 -0.3" conaffinity="1"/>
    <geom name="obs5" pos="1.9 1.5 0.218" size="0.15 0.2 0.01" type="box" rgba="1 0.6 0.8 1" euler="0 -0.01 0.4" conaffinity="1"/>
    <geom name="obs6" pos="0.9 0.6 0.23" size="0.15 0.2 0.01" type="box" rgba="1 1 1 1" euler="0 0.02 -0.2" conaffinity="1"/>
    <geom name="obs7" pos="0.6 1.5 0.16" size="0.15 0.2 0.01" type="box" rgba="1 0.6 0.8 1" euler="0 -0.05 0.5" conaffinity="1"/>
    <geom name="obs8" pos="-0.5 1.5 0.17" size="0.15 0.2 0.01" type="box" rgba="1 1 1 1" euler="0 0.06 0.2" conaffinity="1"/>
    <geom name="obs9" pos="-0.7 0.5 0.22" size="0.15 0.2 0.01" type="box" rgba="1 0.6 0.8 1" euler="0 -0.03 -0.2" conaffinity="1"/>
    <geom name="end" type="cylinder" pos="9.5 1 0.35" size="0.2 0.01 0" rgba="0. 0.8 0. 1" conaffinity="0"/>

    <!-- ======= ROBOT ======= -->
    <body name="base_link" pos="-9 1 0.45" euler="0 0 0">
      <inertial pos="0.018885 0.00062964 0.06018" quat="-0.064773 0.618315 0.0968439 0.777246" mass="4.6733" diaginertia="0.054592 0.0348635 0.0323885"/>
      <joint name="floating_base" type="free" limited="false" frictionloss="0.001" damping="0.01" armature="0."/>
<!--      <joint name="floating_base_xslide" type="slide" axis="1 0 0" limited="false" frictionloss="0.001" damping="0.01" armature="0.00"/>-->
<!--      <joint name="floating_base_yslide" type="slide" axis="0 1 0" limited="false" frictionloss="0.001" damping="0.01" armature="0.00"/>-->
<!--      <joint name="floating_base_zslide" type="slide" axis="0 0 1" limited="false" frictionloss="0.001" damping="0.01" armature="0.00"/>-->
<!--      <joint name="floating_base_xhinge" axis="1 0 0" limited="false" frictionloss="0.0001" damping="0.01" armature="0.00"/>-->
<!--      <joint name="floating_base_yhinge" axis="0 1 0" limited="false" frictionloss="0.001" damping="0.01" armature="0.00"/>-->
<!--      <joint name="floating_base_zhinge" axis="0 0 1" limited="false" frictionloss="0.001" damping="0.01" armature="0.00"/>-->

      <geom name="base1" type="mesh" contype="0" conaffinity="0" group="1" density="0" rgba="0.75294 0 0 1" mesh="base_link"/>
      <geom name="base2" size="0.17 0.077 0.07" pos="0.02 0 0.06" type="box" rgba="0.75294 0 0 0.000987654321"/>
      <geom name="base3" size="0.048 0.0175" pos="0.017241 0.106 0.0613" quat="0.499998 -0.500002 0.5 0.5" type="cylinder" rgba="0.75294 0 0 0.000987654321"/>
      <geom name="base4" size="0.048 0.0175" pos="0.017241 -0.106 0.0613" quat="0.499998 -0.500002 0.5 0.5" type="cylinder" rgba="0.75294 0 0 0.000987654321"/>
      <site name="imu" pos="0 0 0"/>
      <body name="left_thigh" pos="0.017241 0.13399 0.0613" euler="-1.57 0 2.95">
        <inertial pos="0.17494 0.0025294 0.012308" quat="0.0283574 0.728032 0.00169629 0.684954" mass="1.3343" diaginertia="0.00985328 0.00920167 0.00123438"/>
        <joint name="left_hip" pos="0 0 0" axis="0 0 1" range="-0.5 0.5"/>
        <geom name="left_thigh1" type="mesh" contype="0" conaffinity="0" group="1" density="0" rgba="0.89804 0.91765 0 1" mesh="left_thigh"/>
        <geom name="left_thigh2" size="0.1 0.035 0.005" pos="0.085 0 0" type="box" rgba="0 0.91765 0.92941 0.000987654321"/>
        <geom name="left_thigh3" size="0.048 0.0175" pos="0.21 0 -0.02375" type="cylinder" rgba="0 0.91765 0.92941 0.000987654321"/>
        <body name="left_shin" pos="0.21 0 0.0475" euler="0 0 -1.75">
          <inertial pos="0.15612 0.00046249 0.020119" quat="-0.0169558 0.755863 -0.00997261 0.654434" mass="0.94398" diaginertia="0.00396686 0.00358627 0.000682696"/>
          <joint name="left_knee" pos="0 0 0" axis="0 0 1" range="-0.5 0.5"/>
          <geom type="mesh" contype="0" conaffinity="0" group="1" density="0" rgba="0.89804 0.91765 0 1" mesh="left_shin"/>
          <geom size="0.1 0.035 0.005" pos="0.1 0 0" type="box" rgba="0.89804 0 0.92941 0.000987654321"/>
          <body name="left_wheel" pos="0.18 0 0.0305">
            <inertial pos="0 0 0.0012686" quat="0.5 0.5 -0.5 0.5" mass="0.44583" diaginertia="0.0014254 0.00076522 0.00076522"/>
            <joint name="left_ankle" pos="0 0 0" axis="0 0 1" limited="false"/>
            <geom type="mesh" contype="0" conaffinity="0" group="1" density="0" rgba="0.75294 0 0 1" mesh="left_wheel"/>
            <geom size="0.065 0.02" type="cylinder" rgba="0 0 0.75294 0.000987654321"/>
          </body>
        </body>
      </body>
      <body name="right_thigh" pos="0.017241 -0.13501 0.0613" euler="-1.57 0 2.95">
        <inertial pos="0.17494 0.0025279 -0.012308" quat="-0.00169159 0.684955 -0.0283402 0.728032" mass="1.3343" diaginertia="0.00985329 0.00920166 0.00123441"/>
        <joint name="right_hip" pos="0 0 0" axis="0 0 1" range="-0.5 0.5"/>
        <geom name="right_thigh1" type="mesh" contype="0" conaffinity="0" group="1" density="0" rgba="0.89804 0.91765 0 1" mesh="right_thigh"/>
        <geom name="right_thigh2" size="0.1 0.035 0.005" pos="0.085 0 0" type="box" rgba="0 0.91765 0.92941 0.000987654321"/>
        <geom name="right_thigh3" size="0.048 0.0175" pos="0.21 0 0.02375" type="cylinder" rgba="0 0.91765 0.92941 0.000987654321"/>
        <body name="right_shin" pos="0.21 0 -0.0475" euler="0 0 -1.75">
          <inertial pos="0.15612 0.00046556 -0.020119" quat="0.00996675 0.654435 0.0169079 0.755863" mass="0.94398" diaginertia="0.00396686 0.00358627 0.000682701"/>
          <joint name="right_knee" pos="0 0 0" axis="0 0 1" range="-0.5 0.5"/>
          <geom type="mesh" contype="0" conaffinity="0" group="1" density="0" rgba="0.89804 0.91765 0 1" mesh="right_shin"/>
          <geom size="0.1 0.035 0.005" pos="0.1 0 0" type="box" rgba="0.89804 0 0.92941 0.000987654321"/>
          <body name="right_wheel" pos="0.18 0 -0.0305">
            <inertial pos="0 0 -0.0012686" quat="0.5 0.5 -0.5 0.5" mass="0.44583" diaginertia="0.0014254 0.00076522 0.00076522"/>
            <joint name="right_ankle" pos="0 0 0" axis="0 0 1" limited="false"/>
            <geom type="mesh" contype="0" conaffinity="0" group="1" density="0" rgba="0.75294 0 0 1" mesh="right_wheel"/>
            <geom size="0.065 0.02" type="cylinder" rgba="0 0 0.75294 0.000987654321"/>
          </body>
        </body>
      </body>
    </body>
  </worldbody>
  <actuator>
    <position name="left_hip_motor" joint="left_hip" ctrlrange="-5 5" />
    <position name="left_knee_motor" joint="left_knee" ctrlrange="-5 5"/>
    <motor name="left_ankle_motor" joint="left_ankle" ctrlrange="-40 40"/>
    <position name="right_hip_motor" joint="right_hip" ctrlrange="-5 5" />
    <position name="right_knee_motor" joint="right_knee" ctrlrange="-5 5"/>
    <motor name="right_ankle_motor" joint="right_ankle" ctrlrange="-40 40"/>

<!--    <motor name="left_hip_motor" joint="left_hip" />-->
<!--    <motor name="left_knee_motor" joint="left_knee" />-->
<!--    <motor name="left_ankle_motor" joint="left_ankle" />-->
<!--    <motor name="right_hip_motor" joint="right_hip" />-->
<!--    <motor name="right_knee_motor" joint="right_knee" />-->
<!--    <motor name="right_ankle_motor" joint="right_ankle" />-->
  </actuator>

  <sensor>
    <!-- The sensor sequence cannot be changed -->
    <framequat name="Body_Quat" objtype="site" objname="imu" />
    <gyro name="Body_Gyro" site="imu" />
    <accelerometer name="Body_Acc" site="imu" />
  </sensor>

</mujoco>
